// utility function to catch async errors, to be used as a middleware
const catchAsync = (fn) => (req, res, next) => {
  Promise.resolve(fn(req, res, next)).catch((err) => next(err));
};

export default catchAsync;
